Workbook

Sheet Working Data
B3: Project ID | C3: Drive Time | D3: Tilt | E3: Azimuth | F3: Panel QTY | G3: System Rating (kW DC) | H3: Inverter Manufacturer | I3: Array Type | J3: Squirrel Screen | K3: Consumption Monitoring | L3: Truss / Rafter | M3: Reinforce- ments | N3: Rough Electrical Inspection | O3: Interconnection Type | P3: Module Length | Q3: Module Width | R3: Module Weight | S3: # of Arrays | T3: # of reinforcement | U3: Roof Type | V3: Attachment Type | W3: Portrait / Landscape | X3: # of Stories | Y3: Install Season | Z3: Total Direct Time for Project for Hourly Employees (Including Drive Time) | AA3: Total # of Days on Site | AB3: Total # Hourly Empoyees on Site | AC3: Estimated # of Salaried Employees on Site | AD3: Estimated Salary Hours | AE3: Estimated Total Direct Time | AG3: Estimated Total # of People on Site | AH3: Notes
B4: 001 | C4: 21 mins | D4: 33° | E4: 180° | F4: 19 | G4: 6.84 | H4: SolarEdge | I4: Roof Mount | J4: Yes | L4: Truss | M4: No | N4: No | O4: A1 | P4: 67.8 | Q4: 40 | R4: 43 | S4: 1 | T4: 0 | U4: Asphalt Shingles | V4: Flashfoot 2 | W4: Portrait | X4: 2 | Y4: Spring | Z4: 0.79166667 | AA4: 1 | AB4: 2 | AC4: 2 | AD4: =IFERROR(Z4/(AA4*AB4)*AC4*AA4,"") -> 0.79166667 | AE4: =Z4+AD4 -> 1.5833333 | AG4: =AB4+AC4 -> 4
B5: 002 | C5: 23 mins | D5: 45° | E5: 139° | F5: 18 | G5: 6.57 | H5: SolarEdge | I5: Roof Mount | J5: Yes | L5: Rafter | M5: Yes | N5: Yes | O5: A1 | P5: 67.8 | Q5: 40 | R5: 43 | S5: 1 | T5: 2 | U5: Asphalt Shingles | V5: Flashfoot 2 | W5: Portrait | X5: 1 | Y5: Spring | Z5: 1.3958333 | AA5: 2 | AB5: 2 | AC5: 2 | AD5: =IFERROR(Z5/(AA5*AB5)*AC5*AA5,"") -> 1.3958333 | AE5: =Z5+AD5 -> 2.7916667 | AG5: =AB5+AC5 -> 4
B6: 003 | C6: 21 mins | D6: 24° | E6: 180° | F6: 16 | G6: 5.12 | H6: SolarEdge | I6: Roof Mount | J6: No | L6: Truss | M6: No | N6: No | O6: A3 | P6: 66.3 | Q6: 39.4 | R6: 41.2 | S6: 2 | T6: 0 | U6: Asphalt Shingles | V6: Flashfoot 2 | W6: Portrait | X6: 1 | Y6: Spring | Z6: 1.0555556 | AA6: 2 | AB6: 2 | AC6: 2 | AD6: =IFERROR(Z6/(AA6*AB6)*AC6*AA6,"") -> 1.0555556 | AE6: =Z6+AD6 -> 2.1111111 | AG6: =AB6+AC6 -> 4
B7: 004 | C7: 38 mins | D7: 20° | E7: 104° | F7: 27 | G7: 10.8 | H7: Enphase | I7: Roof Mount | J7: No | L7: Truss | M7: No | N7: No | O7: C2 | P7: 79.3 | Q7: 39.4 | R7: 51.8 | S7: 1 | T7: 0 | U7: Asphalt Shingles | V7: Flashfoot 2 | W7: Portrait | X7: 1 | Y7: Spring | Z7: 1.125 | AA7: 2 | AB7: 2 | AC7: 2 | AD7: =IFERROR(Z7/(AA7*AB7)*AC7*AA7,"") -> 1.125 | AE7: =Z7+AD7 -> 2.25 | AG7: =AB7+AC7 -> 4 | AH7: Yes this job and the one below it both happened
B8: 005 | C8: 38 mins | D8: 20° | E8: 180° | F8: 27 | G8: 10.8 | H8: Enphase | I8: Roof Mount | J8: No | L8: Truss | M8: No | N8: No | O8: C2 | P8: 79.3 | Q8: 39.4 | R8: 51.8 | S8: 1 | T8: 0 | U8: Asphalt Shingles | V8: Flashfoot 2 | W8: Both | X8: 1 | Y8: Spring | Z8: 1.125 | AA8: 2 | AB8: 2 | AC8: 2 | AD8: =IFERROR(Z8/(AA8*AB8)*AC8*AA8,"") -> 1.125 | AE8: =Z8+AD8 -> 2.25 | AG8: =AB8+AC8 -> 4 | AH8: Yes this job and the one above it both happened
B9: 006 | C9: 45 mins | D9: 18.4° | E9: 180° | F9: 18 | G9: 6.12 | H9: SolarEdge | I9: Roof Mount | J9: No | L9: Truss | M9: No | N9: No | O9: A1 | P9: 68.5 | Q9: 40.5 | R9: 43.9 | S9: 1 | T9: 0 | U9: Asphalt Shingles | V9: Unknown | W9: Portrait | X9: 1 | Y9: Spring | Z9: 0.70833333 | AA9: 1 | AB9: 2 | AC9: 2 | AD9: =IFERROR(Z9/(AA9*AB9)*AC9*AA9,"") -> 0.70833333 | AE9: =Z9+AD9 -> 1.4166667 | AG9: =AB9+AC9 -> 4
B10: 007 | C10: 24 mins | D10: 26° | E10: 200° | F10: 13 | G10: 4.225 | H10: SolarEdge | I10: Roof Mount | J10: Yes | L10: Truss | M10: No | N10: Yes | O10: A3 | P10: 65.43 | Q10: 39.45 | R10: 41.6 | S10: 1 | T10: 0 | U10: Asphalt Shingles | V10: Flashfoot 2 | W10: Portrait | X10: 2 | Y10: Spring | Z10: 0.8125 | AA10: 1 | AB10: 2 | AC10: 2 | AD10: =IFERROR(Z10/(AA10*AB10)*AC10*AA10,"") -> 0.8125 | AE10: =Z10+AD10 -> 1.625 | AG10: =AB10+AC10 -> 4
B11: 008 | C11: 21 mins | D11: 10° | E11: 205° | F11: 20 | G11: 7.3 | H11: SolarEdge | I11: Roof Mount | J11: No | L11: Rafter | M11: No | N11: Yes | O11: B2 | P11: 67.8 | Q11: 40 | R11: 43 | S11: 1 | T11: 0 | U11: Asphalt Shingles | V11: Flashfoot 2 | W11: Portrait | X11: 1 | Y11: Spring | Z11: 1.59375 | AA11: 3 | AB11: 2 | AC11: 2 | AD11: =IFERROR(Z11/(AA11*AB11)*AC11*AA11,"") -> 1.59375 | AE11: =Z11+AD11 -> 3.1875 | AG11: =AB11+AC11 -> 4
B12: 009 | C12: 30 mins | D12: 18° | E12: 185° | F12: 18 | G12: 5.76 | H12: SolarEdge | I12: Roof Mount | J12: No | L12: Truss | M12: No | N12: No | O12: A2 | P12: 65.94 | Q12: 39.25 | R12: 39.7 | S12: 1 | T12: 0 | U12: Asphalt Shingles | V12: Unknown | W12: Portrait | X12: 2 | Y12: Spring | Z12: 1.0729167 | AA12: 2 | AB12: 2 | AC12: 2 | AD12: =IFERROR(Z12/(AA12*AB12)*AC12*AA12,"") -> 1.0729167 | AE12: =Z12+AD12 -> 2.1458333 | AG12: =AB12+AC12 -> 4
B13: 010 | C13: 6 mins | D13: 31° | E13: 90° | F13: 16 | G13: 5.12 | H13: SolarEdge | I13: Roof Mount | J13: Yes | L13: Rafter | M13: Yes | N13: Yes | O13: B2 | P13: 65.94 | Q13: 39.25 | R13: 39.7 | S13: 1 | T13: 10 | U13: Asphalt Shingles | V13: Flashfoot 2 | W13: Landscape | X13: 1 | Y13: Spring | Z13: 1.40625 | AA13: 2 | AB13: 2 | AC13: 2 | AD13: =IFERROR(Z13/(AA13*AB13)*AC13*AA13,"") -> 1.40625 | AE13: =Z13+AD13 -> 2.8125 | AG13: =AB13+AC13 -> 4
B14: 011 | C14: 16 mins | D14: 26.6° | E14: 130° | F14: 22 | G14: 8.03 | H14: Enphase | I14: Roof Mount | J14: Yes | L14: Truss | M14: No | N14: No | O14: A1 | P14: 67.8 | Q14: 40 | R14: 43 | S14: 2 | T14: 0 | U14: Asphalt Shingles | V14: Flashfoot 2 | W14: Portrait | X14: 2 | Y14: Spring | Z14: 1.8125 | AA14: 4 | AB14: 2 | AC14: 2 | AD14: =IFERROR(Z14/(AA14*AB14)*AC14*AA14,"") -> 1.8125 | AE14: =Z14+AD14 -> 3.625 | AG14: =AB14+AC14 -> 4
B15: 012 | C15: 51 mins | D15: 45° | E15: 180° | F15: 24 | G15: 8.52 | H15: Enphase | I15: Roof Mount | J15: No | L15: Truss | M15: No | N15: No | O15: C* | P15: 67.8 | Q15: 40 | R15: 43 | S15: 1 | T15: 0 | U15: Asphalt Shingles | V15: Flashfoot 2 | W15: Portrait | X15: 2 | Y15: Spring | Z15: 0.53125 | AA15: 1 | AB15: 1 | AC15: 2 | AD15: =IFERROR(Z15/(AA15*AB15)*AC15*AA15,"") -> 1.0625 | AE15: =Z15+AD15 -> 1.59375 | AG15: =AB15+AC15 -> 3
B16: 013 | C16: 10 mins | D16: 45° | E16: 215° | F16: 20 | G16: 7.3 | H16: SolarEdge | I16: Roof Mount | J16: No | L16: Rafter | M16: No | N16: No | O16: C* | P16: 67.8 | Q16: 40 | R16: 43 | S16: 1 | T16: 0 | U16: Asphalt Shingles | V16: Flashfoot 2 | W16: Portrait | X16: 2 | Y16: Spring | Z16: 1.5625 | AA16: 2 | AB16: 2 | AC16: 2 | AD16: =IFERROR(Z16/(AA16*AB16)*AC16*AA16,"") -> 1.5625 | AE16: =Z16+AD16 -> 3.125 | AG16: =AB16+AC16 -> 4
B17: 014 | C17: 36 mins | D17: 35°/27° | E17: 230°/140° | F17: 31 | G17: 11.005 | H17: SolarEdge | I17: Roof Mount | J17: No | L17: Truss | M17: No | N17: No | O17: C3 | P17: 67.8 | Q17: 40 | R17: 43 | S17: 5 | T17: 0 | U17: Asphalt Shingles | V17: Flashfoot 2 | W17: Portrait | X17: 1 | Y17: Spring | Z17: 1.4791667 | AA17: 3 | AB17: 2 | AC17: 2 | AD17: =IFERROR(Z17/(AA17*AB17)*AC17*AA17,"") -> 1.4791667 | AE17: =Z17+AD17 -> 2.9583333 | AG17: =AB17+AC17 -> 4
B18: 015 | C18: 9 mins | D18: 24° | E18: 180° | F18: 32 | G18: 11.36 | H18: Enphase | I18: Roof Mount | J18: No | L18: Truss | M18: No | N18: Yes | O18: C1 | P18: 67.8 | Q18: 40 | R18: 43 | S18: 3 | T18: 0 | U18: Asphalt Shingles | V18: Flashfoot 2 | W18: Portrait | X18: 2 | Y18: Spring | Z18: 1.6875 | AA18: 3 | AB18: 3 | AC18: 2 | AD18: =IFERROR(Z18/(AA18*AB18)*AC18*AA18,"") -> 1.125 | AE18: =Z18+AD18 -> 2.8125 | AG18: =AB18+AC18 -> 5
B19: 016 | C19: 30 mins | D19: 32° | E19: 218° | F19: 23 | G19: 7.59 | H19: SolarEdge | I19: Roof Mount | J19: No | L19: Truss | M19: No | N19: No | O19: A2 | P19: 66.53 | Q19: 39.21 | R19: 39.7 | S19: 2 | T19: 0 | U19: Asphalt Shingles | V19: Flashfoot 2 | W19: Portrait | X19: 1 | Y19: Spring | Z19: 1.2291667 | AA19: 2 | AB19: 2 | AC19: 2 | AD19: =IFERROR(Z19/(AA19*AB19)*AC19*AA19,"") -> 1.2291667 | AE19: =Z19+AD19 -> 2.4583333 | AG19: =AB19+AC19 -> 4
B20: 017 | C20: 21 mins | D20: 24° | E20: 180° | F20: 20 | G20: 6.4 | H20: SolarEdge | I20: Roof Mount | J20: No | L20: Truss | M20: No | N20: No | O20: A1 | P20: 39.4 | Q20: 66.9 | R20: 41 | S20: 2 | T20: 0 | U20: Asphalt Shingles | V20: Flashfoot 2 | W20: Portrait | X20: 2 | Y20: Spring | Z20: 0.83333333 | AA20: 1 | AB20: 2 | AC20: 2 | AD20: =IFERROR(Z20/(AA20*AB20)*AC20*AA20,"") -> 0.83333333 | AE20: =Z20+AD20 -> 1.6666667 | AG20: =AB20+AC20 -> 4
... B29: 026 | C29: 29 mins | D29: 16°/16° | E29: 178°/267° | F29: 12 | G29: 4.44 | H29: Enphase | I29: Roof Mount | J29: Yes | L29: Rafter | M29: No | N29: No | O29: B1 | P29: 70.67 | Q29: 39.98 | R29: 41.9 | S29: 2 | T29: 0 | U29: Asphalt Shingles | V29: Flashfoot 2 | W29: Portrait | X29: 2 | Y29: Fall | Z29: 0.5625 | AA29: 1 | AB29: 2 | AC29: 2 | AD29: =IFERROR(Z29/(AA29*AB29)*AC29*AA29,"") -> 0.5625 | AE29: =Z29+AD29 -> 1.125 | AG29: =AB29+AC29 -> 4
B30: 027 | C30: 28 mins | D30: 20° | F30: 14 | G30: 4.9 | H30: SMA | I30: Roof Mount | J30: No | L30: Truss | M30: No | N30: Yes | O30: A1 | P30: 69.44 | Q30: 41.26 | R30: 46.5 | S30: 2 | T30: 0 | U30: Asphalt Shingles | V30: Flashfoot 2 | W30: Portrait | X30: 2 | Y30: Summer | Z30: 1.3020833 | AA30: 2 | AB30: 3 | AC30: 2 | AD30: =IFERROR(Z30/(AA30*AB30)*AC30*AA30,"") -> 0.86805556 | AE30: =Z30+AD30 -> 2.1701389 | AG30: =AB30+AC30 -> 5
B31: 028 | C31: 25 mins | D31: 24° | E31: 180° | F31: 22 | G31: 7.81 | H31: Enphase | I31: Roof Mount | J31: Yes | L31: Truss | M31: No | N31: Yes | O31: A2 | P31: 68.5 | Q31: 41 | R31: 41 | S31: 3 | T31: 0 | U31: Asphalt Shingles | V31: Flashfoot 2 | W31: Portrait | X31: 2 | Y31: Summer | Z31: 1.625 | AA31: 3 | AB31: 2 | AC31: 2 | AD31: =IFERROR(Z31/(AA31*AB31)*AC31*AA31,"") -> 1.625 | AE31: =Z31+AD31 -> 3.25 | AG31: =AB31+AC31 -> 4
B32: 029 | C32: 4 mins | D32: 25° | E32: 165° | F32: 11 | G32: 4.07 | H32: SolarEdge | I32: Roof Mount | J32: No | L32: Truss | M32: No | N32: Yes | O32: A1 | P32: 70.67 | Q32: 39.98 | R32: 41.9 | S32: 1 | T32: 0 | U32: Asphalt Shingles | V32: Flashfoot 2 | W32: Portrait | X32: 1 | Y32: Summer | Z32: 0.98958333 | AA32: 2 | AB32: 2 | AC32: 2 | AD32: =IFERROR(Z32/(AA32*AB32)*AC32*AA32,"") -> 0.98958333 | AE32: =Z32+AD32 -> 1.9791667 | AG32: =AB32+AC32 -> 4
B33: 030 | C33: 16 mins | D33: 18° | E33: 180° | F33: 13 | G33: 4.29 | H33: Enphase | I33: Roof Mount | J33: No | L33: Truss | M33: No | N33: No | O33: A1 | P33: 66.9 | Q33: 39.4 | R33: 41 | S33: 1 | T33: 0 | U33: Asphalt Shingles | V33: Flashfoot 2 | W33: Portrait | X33: 1 | Y33: Summer | Z33: 0.72916667 | AA33: 2 | AB33: 2 | AC33: 3 | AD33: =IFERROR(Z33/(AA33*AB33)*AC33*AA33,"") -> 1.09375 | AE33: =Z33+AD33 -> 1.8229167 | AG33: =AB33+AC33 -> 5
B34: 031 | C34: 26 mins | D34: 34° | E34: 260° | F34: 15 | G34: 5.1 | H34: SolarEdge | I34: Roof Mount | J34: No | L34: Truss | M34: No | N34: No | O34: A1 | P34: 68.5 | Q34: 40.5 | R34: 43.9 | S34: 2 | T34: 0 | U34: Asphalt Shingles | V34: Flashfoot 2 | W34: Portrait | X34: 2 | Y34: Summer | Z34: 1.0381944 | AA34: 1 | AB34: 3 | AC34: 3 | AD34: =IFERROR(Z34/(AA34*AB34)*AC34*AA34,"") -> 1.0381944 | AE34: =Z34+AD34 -> 2.0763889 | AG34: =AB34+AC34 -> 6
B35: 032 | C35: 12 mins | D35: 19° | E35: 177°/260° | F35: 16 | G35: 5.92 | H35: Enphase | I35: Roof Mount | J35: No | L35: Truss | M35: No | N35: No | O35: A1 | P35: 70.67 | Q35: 39.98 | R35: 41.9 | S35: 2 | T35: 0 | U35: Asphalt Shingles | V35: Flashfoot 2 | W35: Portrait | X35: 1 | Y35: Summer | Z35: 1.0902778 | AA35: 1 | AB35: 3 | AC35: 3 | AD35: =IFERROR(Z35/(AA35*AB35)*AC35*AA35,"") -> 1.0902778 | AE35: =Z35+AD35 -> 2.1805556 | AG35: =AB35+AC35 -> 6
B36: 033 | C36: 13 mins | D36: 18° | E36: 200° | F36: 11 | G36: 4.07 | H36: SolarEdge | I36: Roof Mount | J36: Yes | L36: Rafter | M36: Yes | N36: No | O36: B2 | P36: 70.67 | Q36: 39.98 | R36: 41.9 | S36: 1 | T36: 18 | U36: Asphalt Shingles | V36: Flashfoot 2 | W36: Portrait | X36: 1 | Y36: Summer | Z36: 1.0069444 | AA36: 1 | AB36: 3 | AC36: 3 | AD36: =IFERROR(Z36/(AA36*AB36)*AC36*AA36,"") -> 1.0069444 | AE36: =Z36+AD36 -> 2.0138889 | AG36: =AB36+AC36 -> 6
B37: 034 | C37: 42 mins | D37: 30° | E37: 180° | F37: 13 | G37: 4.81 | H37: SolarEdge | I37: Roof Mount | J37: No | L37: Rafter | M37: Yes | N37: No | O37: C2 | P37: 70.67 | Q37: 39.98 | R37: 41.9 | S37: 1 | T37: 11 | U37: Asphalt Shingles | V37: Flashfoot 2 | W37: Portrait | X37: 1 | Y37: Summer | Z37: 1.2152778 | AA37: 1 | AB37: 3 | AC37: 3 | AD37: =IFERROR(Z37/(AA37*AB37)*AC37*AA37,"") -> 1.2152778 | AE37: =Z37+AD37 -> 2.4305556 | AG37: =AB37+AC37 -> 6
B38: 035 | C38: 15 mins | D38: 25° | E38: 270° | F38: 23 | G38: 7.59 | H38: SolarEdge | I38: Roof Mount | J38: No | L38: Truss | M38: No | N38: No | O38: A1 | P38: 66.53 | Q38: 39.21 | R38: 39.7 | S38: 1 | T38: 0 | U38: Asphalt Shingles | V38: Flashfoot 2 | W38: Portrait | X38: 1 | Y38: Summer | Z38: 1.1145833 | AA38: 1 | AB38: 3 | AC38: 3 | AD38: =IFERROR(Z38/(AA38*AB38)*AC38*AA38,"") -> 1.1145833 | AE38: =Z38+AD38 -> 2.2291667 | AG38: =AB38+AC38 -> 6
B39: 036 | C39: 21 mins | D39: 30° | E39: 180° | F39: 13 | G39: 4.81 | H39: Enphase | I39: Roof Mount | J39: Yes | L39: Truss | M39: No | N39: Yes | O39: A1 | P39: 70.67 | Q39: 39.98 | R39: 41.9 | S39: 1 | T39: 0 | U39: Asphalt Shingles | V39: Flashfoot 2 | W39: Portrait | X39: 1 | Y39: Summer | Z39: 1.0520833 | AA39: 1 | AB39: 3 | AC39: 3 | AD39: =IFERROR(Z39/(AA39*AB39)*AC39*AA39,"") -> 1.0520833 | AE39: =Z39+AD39 -> 2.1041667 | AG39: =AB39+AC39 -> 6
B40: 037 | C40: 26 mins | D40: 38° | E40: 173° | F40: 9 | G40: 4.05 | H40: Enphase | I40: Roof Mount | J40: No | L40: Rafter | M40: No | N40: Yes | O40: A3 | P40: 83.07 | Q40: 41 | R40: 50.71 | S40: 1 | T40: 0 | U40: Standing Seam Metal Roof | V40: S-5! | W40: Landscape | X40: 1 | Y40: Fall | Z40: 2.9583333 | AA40: 3 | AB40: 3 | AC40: 3 | AD40: =IFERROR(Z40/(AA40*AB40)*AC40*AA40,"") -> 2.9583333 | AE40: =Z40+AD40 -> 5.9166667 | AG40: =AB40+AC40 -> 6
B41: 038 | C41: 15 mins | D41: 16° | E41: 192° | F41: 29 | G41: 10.73 | H41: Enphase | I41: Roof Mount | J41: Yes | L41: Truss | M41: No | N41: Yes | O41: C1 | P41: 70.67 | Q41: 39.98 | R41: 41.9 | S41: 2 | T41: 0 | U41: Asphalt Shingles | V41: Flashfoot 2 | W41: Portrait | X41: 2 | Y41: Summer | Z41: 1.58125 | AA41: 2 | AB41: 3 | AC41: 3 | AD41: =IFERROR(Z41/(AA41*AB41)*AC41*AA41,"") -> 1.58125 | AE41: =Z41+AD41 -> 3.1625 | AG41: =AB41+AC41 -> 6
B42: 039 | C42: 25 mins | D42: 18° | E42: 157° | F42: 16 | G42: 6.08 | H42: SolarEdge | I42: Roof Mount | J42: No | L42: Rafter | M42: No | N42: Yes | O42: B2 | P42: 72.4 | Q42: 40.6 | R42: 43 | S42: 2 | T42: 0 | U42: Asphalt Shingles | V42: Flashfoot 2 | W42: Portrait | X42: 1 | Y42: Summer | Z42: 1.1819444 | AA42: 1 | AB42: 3 | AC42: 3 | AD42: =IFERROR(Z42/(AA42*AB42)*AC42*AA42,"") -> 1.1819444 | AE42: =Z42+AD42 -> 2.3638889 | AG42: =AB42+AC42 -> 6
B43: 040 | C43: 22 mins | E43: 148°/240° | F43: 43 | G43: 15.695 | H43: Enphase | I43: Roof Mount | J43: No | L43: Truss | M43: No | N43: No | O43: C1 | P43: 67.8 | Q43: 40 | R43: 43 | S43: 8 | T43: 0 | U43: Asphalt Shingles | V43: Flashfoot 2 | W43: Portrait | X43: 2 | Y43: Summer | Z43: 3.1770833 | AA43: 3 | AB43: 3 | AC43: 3 | AD43: =IFERROR(Z43/(AA43*AB43)*AC43*AA43,"") -> 3.1770833 | AE43: =Z43+AD43 -> 6.3541667 | AG43: =AB43+AC43 -> 6
B44: 041 | C44: 36 mins | D44: 30° | E44: 260° | F44: 36 | G44: 13.32 | H44: SolarEdge | I44: Roof Mount | J44: No | L44: Truss | M44: No | N44: No | O44: C* | P44: 70.67 | Q44: 39.98 | R44: 41.9 | S44: 1 | T44: 0 | U44: Asphalt Shingles | V44: Flashfoot 2 | W44: Portrait | X44: 1 | Y44: Summer | Z44: 2.2875 | AA44: 3 | AB44: 3 | AC44: 3 | AD44: =IFERROR(Z44/(AA44*AB44)*AC44*AA44,"") -> 2.2875 | AE44: =Z44+AD44 -> 4.575 | AG44: =AB44+AC44 -> 6
B45: 042 | C45: 25 mins | D45: 10° | E45: 162° | F45: 16 | G45: 5.28 | H45: SolarEdge | I45: Roof Mount | J45: No | L45: Truss | M45: No | N45: Yes | O45: B2 | P45: 66.9 | Q45: 39.4 | R45: 41 | S45: 1 | T45: 0 | U45: Standing Seam Metal Roof | V45: S-5! | W45: Portrait | X45: 1 | Y45: Summer | Z45: 0.72916667 | AA45: 1 | AB45: 2 | AC45: 3 | AD45: =IFERROR(Z45/(AA45*AB45)*AC45*AA45,"") -> 1.09375 | AE45: =Z45+AD45 -> 1.8229167 | AG45: =AB45+AC45 -> 5
B46: 044 | C46: 22 mins | D46: 20°/37° | E46: 215°/125° | F46: 21 | G46: 7.77 | H46: Enphase | I46: Roof Mount | J46: Yes | L46: Truss | M46: No | N46: No | O46: A1 | P46: 70.67 | Q46: 39.98 | R46: 41.9 | S46: 3 | T46: 0 | U46: Asphalt Shingles | V46: Flashfoot 2 | W46: Portrait | X46: 2 | Y46: Fall | Z46: 0.98958333 | AA46: 2 | AB46: 3 | AC46: 3 | AD46: =IFERROR(Z46/(AA46*AB46)*AC46*AA46,"") -> 0.98958333 | AE46: =Z46+AD46 -> 1.9791667 | AG46: =AB46+AC46 -> 6
B47: 045 | C47: 10 mins | D47: 23° | E47: 135° | F47: 9 | G47: 3.33 | H47: Enphase | I47: Roof Mount | J47: Yes | L47: Rafter | M47: Yes | N47: Yes | O47: B2 | P47: 70.67 | Q47: 39.98 | R47: 41.9 | S47: 1 | T47: 11 | U47: Asphalt Shingles | V47: Flashfoot 2 | W47: Portrait | X47: 1 | Y47: Summer | Z47: 1.3819444 | AA47: 2 | AB47: 3 | AC47: 3 | AD47: =IFERROR(Z47/(AA47*AB47)*AC47*AA47,"") -> 1.3819444 | AE47: =Z47+AD47 -> 2.7638889 | AG47: =AB47+AC47 -> 6
B48: 046 | C48: 16 mins | D48: 30° | E48: 180° | F48: 54 | G48: 23.22 | H48: Enphase | I48: Ground Mount | J48: No | L48: Grount Mount | M48: No | N48: No | O48: C2 | P48: 81.89 | Q48: 40.56 | R48: 55.11 | S48: 2 | T48: 0 | U48: Ground Mount | V48: Ground Mount | W48: Portrait | X48: 0 | Y48: Fall | Z48: 4.3611111 | AA48: 8 | AB48: 3 | AC48: 3 | AD48: =IFERROR(Z48/(AA48*AB48)*AC48*AA48,"") -> 4.3611111 | AE48: =Z48+AD48 -> 8.7222222 | AG48: =AB48+AC48 -> 6
B49: 047 | C49: 18 mins | D49: 28° | E49: 200° | F49: 14 | G49: 5.18 | H49: SolarEdge | I49: Roof Mount | J49: Yes | L49: Truss | M49: No | N49: No | O49: A1 | P49: 70.67 | Q49: 39.98 | R49: 41.9 | S49: 1 | T49: 0 | U49: Asphalt Shingles | V49: Flashfoot 2 | W49: Portrait | X49: 1 | Y49: Fall | Z49: 0.5625 | AA49: 2 | AB49: 1 | AC49: 3 | AD49: =IFERROR(Z49/(AA49*AB49)*AC49*AA49,"") -> 1.6875 | AE49: =Z49+AD49 -> 2.25 | AG49: =AB49+AC49 -> 4
B50: 049 | C50: 43 mins | D50: 25° | E50: 180° | F50: 20 | G50: 7.4 | H50: Enphase | I50: Roof Mount | J50: No | L50: Truss | M50: No | N50: No | O50: A3 | P50: 70.67 | Q50: 39.98 | R50: 41.9 | S50: 1 | T50: 0 | U50: Asphalt Shingles | V50: Flashfoot 2 | W50: Portrait | X50: 2 | Y50: Fall | Z50: 1.7291667 | AA50: 3 | AB50: 2 | AC50: 3 | AD50: =IFERROR(Z50/(AA50*AB50)*AC50*AA50,"") -> 2.59375 | AE50: =Z50+AD50 -> 4.3229167 | AG50: =AB50+AC50 -> 5
...

Sheet Technical Analysis
C2: Analysis of MSP Residential and Commercial Data
B3: Year | C3: 2019 | D3: 2020 | E3: 2021 | F3: 2022 | G3: 2023 | H3: 2024 | I3: 2025 | J3: 2025 Estimated Full Year Info Based on Data | K3: 2025 Estimated Full Year of Info Based on Business Plan
B4: # of Installs | C4: 55 | D4: 62 | E4: 81 | F4: 86 | G4: 84 | H4: 119 | I4: #REF!
B5: kW Installed | C5: 480 | D5: 650 | E5: 670 | F5: 828 | G5: 947 | H5: 1249 | I5: #REF!
B6: Install Revenue | C6: 1400000 | D6: 1675000 | E6: 1810000 | F6: 2339533 | G6: 2668936 | H6: 3266869 | I6: #REF!
B7: Est. CoGs | C7: - | D7: - | E7: - | F7: - | G7: 1681254 | H7: 2062602 | I7: #REF!
B8: Est. Margin $ | C8: - | D8: - | E8: - | F8: - | G8: 984551 | H8: 1221323 | I8: #REF!
B9: Estimated Direct Labor Costs | G9: 185660 | H9: 267683 | I9: #REF!
B10: Estimated EC Cost | C10: - | D10: - | E10: - | F10: - | G10: 154200 | H10: 204936 | I10: #REF!
B11: Actual EC Cost | C11: - | D11: - | E11: - | F11: - | G11: 113558 | H11: 85130 | I11: #REF!
B12: Average System Price | C12: - | D12: - | E12: 22353 | F12: 27203 | G12: 31773 | H12: 27685 | I12: #DIV/0!
B13: Median System Price | D13: - | E13: 19206 | F13: 24305 | G13: 26342 | H13: 21978 | I13: #REF!
B14: Average kW/Install | C14: - | D14: - | E14: 8.3 | F14: 8.76 | G14: 11.28 | H14: 10.5 | I14: =I5/I4 -> #REF!
B15: Median kW/Install | C15: - | D15: - | E15: 6.6 | F15: 7.79 | G15: 8.3 | H15: 7.82 | I15: #REF!
B16: Average $/W | C16: 2.93 | D16: 2.61 | E16: 2.7 | F16: 2.83 | G16: 2.82 | H16: 2.62 | I16: =I6/(I5*1000) -> #REF!
B17: Median $/W | C17: - | D17: - | E17: 2.84 | F17: 2.98 | G17: 3.01 | H17: 2.83 | I17: #REF!
B18: # of People | C18: 5 | D18: 8 | E18: 9 | F18: 10 | G18: 12 | H18: 14 | I18: 15
B20: Utility Breakdown - Count
B21: MGE | C21: - | D21: - | E21: 40 | F21: 28 | G21: 24 | H21: 46 | I21: #REF!
B22: Alliant | C22: - | D22: - | E22: 23 | F22: 50 | G22: 46 | H22: 55 | I22: #REF!
B23: WE Energies | C23: - | D23: - | E23: 6 | F23: 1 | G23: 2 | H23: 2 | I23: #REF!
B24: Other | C24: - | D24: - | E24: 10 | F24: 7 | G24: 12 | H24: 10 | I24: #REF!
B26: Utility Breakdown - Percent
B27: MGE | C27: - | D27: - | E27: =E21/E$4 -> 0.49382716 | F27: =F21/F$4 -> 0.3255814 | G27: 0.286 | H27: 0.365 | I27: =I21/$I$4 -> #VALUE!
B28: Alliant | C28: - | D28: - | E28: =E22/E$4 -> 0.28395062 | F28: =F22/F$4 -> 0.58139535 | G28: 0.548 | H28: 0.437 | I28: =I22/$I$4 -> #VALUE!
B29: WE Energies | C29: - | D29: - | E29: =E23/E$4 -> 0.074074074 | F29: =F23/F$4 -> 0.011627907 | G29: 0.024 | H29: 0.016 | I29: =I23/$I$4 -> #VALUE!
B30: Other | C30: - | D30: - | E30: =E24/E$4 -> 0.12345679 | F30: =F24/F$4 -> 0.081395349 | G30: 0.143 | H30: 0.079 | I30: =I24/$I$4 -> #REF!
B32: Inverter Manufacturer - Count
B33: Enphase | C33: - | D33: - | E33: 37 | F33: 43 | G33: 63 | H33: 106 | I33: #VALUE!
B34: SolarEdge | C34: - | D34: - | E34: 41 | F34: 41 | G34: 16 | H34: 5 | I34: #VALUE!
B35: SMA | C35: - | D35: - | E35: 2 | F35: 2 | G35: 4 | H35: 1 | I35: #VALUE!
B36: Other | C36: - | D36: - | E36: 1 | F36: 0 | G36: 1 | H36: 4 | I36: #VALUE!
B38: Inverter Manufacturer - Percent
B39: Enphase | C39: - | D39: - | E39: =E33/E$4 -> 0.45679012 | F39: =F33/F$4 -> 0.5 | G39: 0.75 | H39: 0.841 | I39: =I33/$I$4 -> #VALUE!
B40: SolarEdge | C40: - | D40: - | E40: =E34/E$4 -> 0.50617284 | F40: =F34/F$4 -> 0.47674419 | G40: 0.19 | H40: 0.04 | I40: =I34/$I$4 -> #VALUE!
B41: SMA | C41: - | D41: - | E41: =E35/E$4 -> 0.024691358 | F41: =F35/F$4 -> 0.023255814 | G41: 0.048 | H41: 0.008 | I41: =I35/$I$4 -> #VALUE!
B42: Other | C42: - | D42: - | E42: =E36/E$4 -> 0.012345679 | F42: =F36/F$4 -> 0 | G42: 0.012 | H42: 0.032 | I42: =I36/$I$4 -> #VALUE!
B44: Panel Manufacturer - Count
B45: REC | C45: - | D45: - | E45: 19 | F45: 30 | G45: 51 | H45: 98 | I45: #REF!
B46: Silfab | C46: - | D46: - | E46: 32 | F46: 19 | G46: 4 | H46: 0 | I46: #REF!
...

Sheet CORE METRICS +
H2: OVERALL - RESIDENTIAL + COMMERCIAL
H3: Budgetted Bookings | K3: Actual Bookings (non service) | N3: Permits | S3: Utility Applications | X3: Budgetted Install Schedule | AA3: Planned Installs at Contract Signing (non service) | AD3: Actual Installations (non service) | AH3: Budgeted Bookings vs Actual Bookings | AL3: Budgeted Installs vs Actual Installs | AP3: Planned Installs at Contract vs Actual Install
F4: Month | G4: Derived Booking Value percentage per Month | H4: QTY Booked | I4: kW Booked | J4: Contract Value of Booked Systems | K4: QTY Booked | L4: kW Booked | M4: Contract Value of Booked Systems | N4: Permits Submitted | O4: Permits Approved | P4: Jobs with Unsubmitted Permits | Q4: Outstanding Submitted Permits MTD or at Months End | R4: Total Approved But Uninstalled Permits MTD or at Month End | S4: Utility Applications Submitted | T4: Utility Applications Approved | U4: Jobs with Unsubmitted Utility Applications | V4: Outstanding Submitted Utility Applications MTD or at Months End | W4: Total Approved but Uninstalled Utility Applications MTD or at Months End | X4: QTY Installed | Y4: kW Installed | Z4: Contract Value of Installed Systems | AA4: QTY Installed | AB4: kW Installed | AC4: Contract Value of Installed Systems | AD4: QTY Installed | AE4: kW Installed | AF4: Contract Value of Installed Systems | AH4: QTY Booked | AI4: kW Booked | AJ4: Contract Value of Booked Systems | AL4: QTY Installed | AM4: kW Installed | AN4: Contract Value of Installed Systems | AP4: QTY Installed | AQ4: kW Installed | AR4: Contract Value of Installed Systems
B5: >=1/1/23 | C5: <1/1/24 | D5: 0 | E5: =CONCATENATE(LEFT(B5,FIND(">=",B5) + 1),RIGHT(C5,LEN(C5) - (FIND("<",C5)))) -> >=1/1/24 | F5: 2023 | G5: N/A | K5: =COUNTIFS(#REF!,$B5,#REF!,$C5) -> #REF! | L5: =SUMIFS(#REF!,#REF!,$B5,#REF!,$C5) -> #REF! | M5: =SUMIFS(#REF!,#REF!,$B5,#REF!,$C5) -> #REF! | N5: =COUNTIFS(#REF!,$B5,#REF!,$C5) -> #REF! | O5: =COUNTIFS(#REF!,$B5,#REF!,$C5) -> #REF! | P5: =IF(MONTH(TODAY())>=$D5,COUNTIFS(#REF!,$C5)-COUNTIFS(#REF!,$C5),"") -> #REF! | Q5: 0 | R5: =IF(MONTH(TODAY())>=$D5,COUNTIFS(#REF!,$C5)-COUNTIFS(#REF!,$C5),"") -> #REF! | S5: =COUNTIFS(#REF!,$B5,#REF!,$C5) -> #REF! | T5: =COUNTIFS(#REF!,$B5,#REF!,$C5) -> #REF! | U5: =IF(MONTH(TODAY())>=$D5,COUNTIFS(#REF!,$C5)-COUNTIFS(#REF!,$C5),"") -> #REF! | V5: 0 | W5: =IF(MONTH(TODAY())>=$D5,COUNTIFS(#REF!,$C5)-COUNTIFS(#REF!,$C5),"") -> #REF! | AA5: =COUNTIFS(#REF!,$B5,#REF!,$C5) -> #REF! | AB5: =SUMIFS(#REF!,#REF!,$B5,#REF!,$C5) -> #REF! | AC5: =SUMIFS(#REF!,#REF!,$B5,#REF!,$C5) -> #REF! | AP5: =IF(MONTH(TODAY())>=$D5,AD5-AA5,"") -> #REF! | AQ5: =IF(MONTH(TODAY())>=$D5,AE5-AB5,"") -> #REF! | AR5: =IF(MONTH(TODAY())>=$D5,AF5-AC5,"") -> #REF!
B6: >=1/1/24 | C6: <2/1/24 | D6: 1 | E6: =CONCATENATE(LEFT(B6,FIND(">=",B6) + 1),RIGHT(C6,LEN(C6) - (FIND("<",C6)))) -> >=2/1/24 | F6: January | G6: =J6/$J$19 -> 0.0603 | H6: =H55+H95 -> 6 | I6: =I55+I95 -> 101.65917 | J6: 211050 | K6: =COUNTIFS(#REF!,$B6,#REF!,$C6) -> #REF! | L6: =SUMIFS(#REF!,#REF!,$B6,#REF!,$C6) -> #REF! | M6: =SUMIFS(#REF!,#REF!,$B6,#REF!,$C6) -> #REF! | N6: =COUNTIFS(#REF!,$B6,#REF!,$C6) -> #REF! | O6: =COUNTIFS(#REF!,$B6,#REF!,$C6) -> #REF! | P6: =IF(MONTH(TODAY())>=$D6,COUNTIFS(#REF!,$C6)-COUNTIFS(#REF!,$C6),"") -> #REF! | Q6: 0 | R6: =IF(MONTH(TODAY())>=$D6,COUNTIFS(#REF!,$C6)-COUNTIFS(#REF!,$C6),"") -> #REF! | S6: =COUNTIFS(#REF!,$B6,#REF!,$C6) -> #REF! | T6: =COUNTIFS(#REF!,$B6,#REF!,$C6) -> #REF! | U6: =IF(MONTH(TODAY())>=$D6,COUNTIFS(#REF!,$C6)-COUNTIFS(#REF!,$C6),"") -> #REF! | V6: 0 | W6: =IF(MONTH(TODAY())>=$D6,COUNTIFS(#REF!,$C6)-COUNTIFS(#REF!,$C6),"") -> #REF! | X6: 4 | Y6: =Y55+Y95 -> 40 | Z6: =Z55+Z95 -> 111072.42 | AA6: =COUNTIFS(#REF!,$B6,#REF!,$C6) -> #REF! | AB6: =SUMIFS(#REF!,#REF!,$B6,#REF!,$C6) -> #REF! | AC6: =SUMIFS(#REF!,#REF!,$B6,#REF!,$C6) -> #REF! | AD6: =COUNTIFS(#REF!,$B6,#REF!,$C6) -> #REF! | AE6: =SUMIFS(#REF!,#REF!,$B6,#REF!,$C6) -> #REF! | AF6: =SUMIFS(#REF!,#REF!,$B6,#REF!,$C6) -> #REF! | AH6: =IF(MONTH(TODAY())>=$D6,K6-H6,"") -> #REF! | AI6: =IF(MONTH(TODAY())>=$D6,L6-I6,"") -> #REF! | AJ6: =IF(MONTH(TODAY())>=$D6,M6-J6,"") -> #REF! | AL6: =IF(MONTH(TODAY())>=$D6,AD6-X6,"") -> #REF! | AM6: =IF(MONTH(TODAY())>=$D6,AE6-Y6,"") -> #REF! | AN6: =IF(MONTH(TODAY())>=$D6,AF6-Z6,"") -> #REF! | AP6: =IF(MONTH(TODAY())>=$D6,AD6-AA6,"") -> #REF! | AQ6: =IF(MONTH(TODAY())>=$D6,AE6-AB6,"") -> #REF! | AR6: =IF(MONTH(TODAY())>=$D6,AF6-AC6,"") -> #REF!
B7: >=2/1/24 | C7: <3/1/24 | D7: 2 | E7: =CONCATENATE(LEFT(B7,FIND(">=",B7) + 1),RIGHT(C7,LEN(C7) - (FIND("<",C7)))) -> >=3/1/24 | F7: February | G7: =J7/$J$19 -> 0.0547 | H7: =H56+H96 -> 6 | I7: =I56+I96 -> 94.60047 | J7: 191450 | K7: =COUNTIFS(#REF!,$B7,#REF!,$C7) -> #REF! | L7: =SUMIFS(#REF!,#REF!,$B7,#REF!,$C7) -> #REF! | M7: =SUMIFS(#REF!,#REF!,$B7,#REF!,$C7) -> #REF! | N7: =COUNTIFS(#REF!,$B7,#REF!,$C7) -> #REF! | O7: =COUNTIFS(#REF!,$B7,#REF!,$C7) -> #REF! | P7: =IF(MONTH(TODAY())>=$D7,COUNTIFS(#REF!,$C7)-COUNTIFS(#REF!,$C7),"") -> #REF! | R7: =IF(MONTH(TODAY())>=$D7,COUNTIFS(#REF!,$C7)-COUNTIFS(#REF!,$C7),"") -> #REF! | S7: =COUNTIFS(#REF!,$B7,#REF!,$C7) -> #REF! | T7: =COUNTIFS(#REF!,$B7,#REF!,$C7) -> #REF! | U7: =IF(MONTH(TODAY())>=$D7,COUNTIFS(#REF!,$C7)-COUNTIFS(#REF!,$C7),"") -> #REF! | W7: =IF(MONTH(TODAY())>=$D7,COUNTIFS(#REF!,$C7)-COUNTIFS(#REF!,$C7),"") -> #REF! | X7: 2 | Y7: =Y56+Y96 -> 20 | Z7: =Z56+Z96 -> 55536.21 | AA7: =COUNTIFS(#REF!,$B7,#REF!,$C7) -> #REF! | AB7: =SUMIFS(#REF!,#REF!,$B7,#REF!,$C7) -> #REF! | AC7: =SUMIFS(#REF!,#REF!,$B7,#REF!,$C7) -> #REF! | AD7: =COUNTIFS(#REF!,$B7,#REF!,$C7) -> #REF! | AE7: =SUMIFS(#REF!,#REF!,$B7,#REF!,$C7) -> #REF! | AF7: =SUMIFS(#REF!,#REF!,$B7,#REF!,$C7) -> #REF! | AH7: =IF(MONTH(TODAY())>=$D7,K7-H7,"") -> #REF! | AI7: =IF(MONTH(TODAY())>=$D7,L7-I7,"") -> #REF! | AJ7: =IF(MONTH(TODAY())>=$D7,M7-J7,"") -> #REF! | AL7: =IF(MONTH(TODAY())>=$D7,AD7-X7,"") -> #REF! | AM7: =IF(MONTH(TODAY())>=$D7,AE7-Y7,"") -> #REF! | AN7: =IF(MONTH(TODAY())>=$D7,AF7-Z7,"") -> #REF! | AP7: =IF(MONTH(TODAY())>=$D7,AD7-AA7,"") -> #REF! | AQ7: =IF(MONTH(TODAY())>=$D7,AE7-AB7,"") -> #REF! | AR7: =IF(MONTH(TODAY())>=$D7,AF7-AC7,"") -> #REF!
B8: >=3/1/24 | C8: <4/1/24 | D8: 3 | E8: =CONCATENATE(LEFT(B8,FIND(">=",B8) + 1),RIGHT(C8,LEN(C8) - (FIND("<",C8)))) -> >=4/1/24 | F8: March | G8: =J8/$J$19 -> 0.0804 | H8: =H57+H97 -> 9 | I8: =I57+I97 -> 126.99488 | J8: 281400 | K8: =COUNTIFS(#REF!,$B8,#REF!,$C8) -> #REF! | L8: =SUMIFS(#REF!,#REF!,$B8,#REF!,$C8) -> #REF! | M8: =SUMIFS(#REF!,#REF!,$B8,#REF!,$C8) -> #REF! | N8: =COUNTIFS(#REF!,$B8,#REF!,$C8) -> #REF! | O8: =COUNTIFS(#REF!,$B8,#REF!,$C8) -> #REF! | P8: =IF(MONTH(TODAY())>=$D8,COUNTIFS(#REF!,$C8)-COUNTIFS(#REF!,$C8),"") -> #REF! | R8: =IF(MONTH(TODAY())>=$D8,COUNTIFS(#REF!,$C8)-COUNTIFS(#REF!,$C8),"") -> #REF! | S8: =COUNTIFS(#REF!,$B8,#REF!,$C8) -> #REF! | T8: =COUNTIFS(#REF!,$B8,#REF!,$C8) -> #REF! | U8: =IF(MONTH(TODAY())>=$D8,COUNTIFS(#REF!,$C8)-COUNTIFS(#REF!,$C8),"") -> #REF! | W8: =IF(MONTH(TODAY())>=$D8,COUNTIFS(#REF!,$C8)-COUNTIFS(#REF!,$C8),"") -> #REF! | X8: 7 | Y8: =Y57+Y97 -> 113.5 | Z8: =Z57+Z97 -> 238422.69 | AA8: =COUNTIFS(#REF!,$B8,#REF!,$C8) -> #REF! | AB8: =SUMIFS(#REF!,#REF!,$B8,#REF!,$C8) -> #REF! | AC8: =SUMIFS(#REF!,#REF!,$B8,#REF!,$C8) -> #REF! | AD8: =COUNTIFS(#REF!,$B8,#REF!,$C8) -> #REF! | AE8: =SUMIFS(#REF!,#REF!,$B8,#REF!,$C8) -> #REF! | AF8: =SUMIFS(#REF!,#REF!,$B8,#REF!,$C8) -> #REF! | AH8: =IF(MONTH(TODAY())>=$D8,K8-H8,"") -> #REF! | AI8: =IF(MONTH(TODAY())>=$D8,L8-I8,"") -> #REF! | AJ8: =IF(MONTH(TODAY())>=$D8,M8-J8,"") -> #REF! | AL8: =IF(MONTH(TODAY())>=$D8,AD8-X8,"") -> #REF! | AM8: =IF(MONTH(TODAY())>=$D8,AE8-Y8,"") -> #REF! | AN8: =IF(MONTH(TODAY())>=$D8,AF8-Z8,"") -> #REF! | AP8: =IF(MONTH(TODAY())>=$D8,AD8-AA8,"") -> #REF! | AQ8: =IF(MONTH(TODAY())>=$D8,AE8-AB8,"") -> #REF! | AR8: =IF(MONTH(TODAY())>=$D8,AF8-AC8,"") -> #REF!
B9: >=4/1/24 | C9: <5/1/24 | D9: 4 | E9: =CONCATENATE(LEFT(B9,FIND(">=",B9) + 1),RIGHT(C9,LEN(C9) - (FIND("<",C9)))) -> >=5/1/24 | F9: April | G9: =J9/$J$19 -> 0.1018 | H9: =H58+H98 -> 11 | I9: =I58+I98 -> 153.96921 | J9: 356300 | K9: =COUNTIFS(#REF!,$B9,#REF!,$C9) -> #REF! | L9: =SUMIFS(#REF!,#REF!,$B9,#REF!,$C9) -> #REF! | M9: =SUMIFS(#REF!,#REF!,$B9,#REF!,$C9) -> #REF! | N9: =COUNTIFS(#REF!,$B9,#REF!,$C9) -> #REF! | O9: =COUNTIFS(#REF!,$B9,#REF!,$C9) -> #REF! | P9: =IF(MONTH(TODAY())>=$D9,COUNTIFS(#REF!,$C9)-COUNTIFS(#REF!,$C9),"") | R9: =IF(MONTH(TODAY())>=$D9,COUNTIFS(#REF!,$C9)-COUNTIFS(#REF!,$C9),"") | S9: =COUNTIFS(#REF!,$B9,#REF!,$C9) -> #REF! | T9: =COUNTIFS(#REF!,$B9,#REF!,$C9) -> #REF! | U9: =IF(MONTH(TODAY())>=$D9,COUNTIFS(#REF!,$C9)-COUNTIFS(#REF!,$C9),"") | W9: =IF(MONTH(TODAY())>=$D9,COUNTIFS(#REF!,$C9)-COUNTIFS(#REF!,$C9),"") | X9: 11 | Y9: =Y58+Y98 -> 153.5 | Z9: =Z58+Z98 -> 349495.11 | AA9: =COUNTIFS(#REF!,$B9,#REF!,$C9) -> #REF! | AB9: =SUMIFS(#REF!,#REF!,$B9,#REF!,$C9) -> #REF! | AC9: =SUMIFS(#REF!,#REF!,$B9,#REF!,$C9) -> #REF! | AD9: =COUNTIFS(#REF!,$B9,#REF!,$C9) -> #REF! | AE9: =SUMIFS(#REF!,#REF!,$B9,#REF!,$C9) -> #REF! | AF9: =SUMIFS(#REF!,#REF!,$B9,#REF!,$C9) -> #REF! | AH9: =IF(MONTH(TODAY())>=$D9,K9-H9,"") | AI9: =IF(MONTH(TODAY())>=$D9,L9-I9,"") | AJ9: =IF(MONTH(TODAY())>=$D9,M9-J9,"") | AL9: =IF(MONTH(TODAY())>=$D9,AD9-X9,"") | AM9: =IF(MONTH(TODAY())>=$D9,AE9-Y9,"") | AN9: =IF(MONTH(TODAY())>=$D9,AF9-Z9,"") | AP9: =IF(MONTH(TODAY())>=$D9,AD9-AA9,"") | AQ9: =IF(MONTH(TODAY())>=$D9,AE9-AB9,"") | AR9: =IF(MONTH(TODAY())>=$D9,AF9-AC9,"")
B10: >=5/1/24 | C10: <6/1/24 | D10: 5 | E10: =CONCATENATE(LEFT(B10,FIND(">=",B10) + 1),RIGHT(C10,LEN(C10) - (FIND("<",C10)))) -> >=6/1/24 | F10: May | G10: =J10/$J$19 -> 0.1068 | H10: =H59+H99 -> 12 | I10: =I59+I99 -> 160.27162 | J10: 373800 | K10: =COUNTIFS(#REF!,$B10,#REF!,$C10) -> #REF! | L10: =SUMIFS(#REF!,#REF!,$B10,#REF!,$C10) -> #REF! | M10: =SUMIFS(#REF!,#REF!,$B10,#REF!,$C10) -> #REF! | N10: =COUNTIFS(#REF!,$B10,#REF!,$C10) -> #REF! | O10: =COUNTIFS(#REF!,$B10,#REF!,$C10) -> #REF! | P10: =IF(MONTH(TODAY())>=$D10,COUNTIFS(#REF!,$C10)-COUNTIFS(#REF!,$C10),"") | R10: =IF(MONTH(TODAY())>=$D10,COUNTIFS(#REF!,$C10)-COUNTIFS(#REF!,$C10),"") | S10: =COUNTIFS(#REF!,$B10,#REF!,$C10) -> #REF! | T10: =COUNTIFS(#REF!,$B10,#REF!,$C10) -> #REF! | U10: =IF(MONTH(TODAY())>=$D10,COUNTIFS(#REF!,$C10)-COUNTIFS(#REF!,$C10),"") | W10: =IF(MONTH(TODAY())>=$D10,COUNTIFS(#REF!,$C10)-COUNTIFS(#REF!,$C10),"") | X10: 11 | Y10: =Y59+Y99 -> 153.5 | Z10: =Z59+Z99 -> 349495.11 | AA10: =COUNTIFS(#REF!,$B10,#REF!,$C10) -> #REF! | AB10: =SUMIFS(#REF!,#REF!,$B10,#REF!,$C10) -> #REF! | AC10: =SUMIFS(#REF!,#REF!,$B10,#REF!,$C10) -> #REF! | AD10: =COUNTIFS(#REF!,$B10,#REF!,$C10) -> #REF! | AE10: =SUMIFS(#REF!,#REF!,$B10,#REF!,$C10) -> #REF! | AF10: =SUMIFS(#REF!,#REF!,$B10,#REF!,$C10) -> #REF! | AH10: =IF(MONTH(TODAY())>=$D10,K10-H10,"") | AI10: =IF(MONTH(TODAY())>=$D10,L10-I10,"") | AJ10: =IF(MONTH(TODAY())>=$D10,M10-J10,"") | AL10: =IF(MONTH(TODAY())>=$D10,AD10-X10,"") | AM10: =IF(MONTH(TODAY())>=$D10,AE10-Y10,"") | AN10: =IF(MONTH(TODAY())>=$D10,AF10-Z10,"") | AP10: =IF(MONTH(TODAY())>=$D10,AD10-AA10,"") | AQ10: =IF(MONTH(TODAY())>=$D10,AE10-AB10,"") | AR10: =IF(MONTH(TODAY())>=$D10,AF10-AC10,"")
B11: >=6/1/24 | C11: <7/1/24 | D11: 6 | E11: =CONCATENATE(LEFT(B11,FIND(">=",B11) + 1),RIGHT(C11,LEN(C11) - (FIND("<",C11)))) -> >=7/1/24 | F11: June | G11: =J11/$J$19 -> 0.1037 | H11: =H60+H100 -> 12 | I11: =I60+I100 -> 156.36413 | J11: 362950 | K11: =COUNTIFS(#REF!,$B11,#REF!,$C11) -> #REF! | L11: =SUMIFS(#REF!,#REF!,$B11,#REF!,$C11) -> #REF! | M11: =SUMIFS(#REF!,#REF!,$B11,#REF!,$C11) -> #REF! | N11: =COUNTIFS(#REF!,$B11,#REF!,$C11) -> #REF! | O11: =COUNTIFS(#REF!,$B11,#REF!,$C11) -> #REF! | P11: =IF(MONTH(TODAY())>=$D11,COUNTIFS(#REF!,$C11)-COUNTIFS(#REF!,$C11),"") | R11: =IF(MONTH(TODAY())>=$D11,COUNTIFS(#REF!,$C11)-COUNTIFS(#REF!,$C11),"") | S11: =COUNTIFS(#REF!,$B11,#REF!,$C11) -> #REF! | T11: =COUNTIFS(#REF!,$B11,#REF!,$C11) -> #REF! | U11: =IF(MONTH(TODAY())>=$D11,COUNTIFS(#REF!,$C11)-COUNTIFS(#REF!,$C11),"") | W11: =IF(MONTH(TODAY())>=$D11,COUNTIFS(#REF!,$C11)-COUNTIFS(#REF!,$C11),"") | X11: 11 | Y11: =Y60+Y100 -> 153.5 | Z11: =Z60+Z100 -> 349495.11 | AA11: =COUNTIFS(#REF!,$B11,#REF!,$C11) -> #REF! | AB11: =SUMIFS(#REF!,#REF!,$B11,#REF!,$C11) -> #REF! | AC11: =SUMIFS(#REF!,#REF!,$B11,#REF!,$C11) -> #REF! | AD11: =COUNTIFS(#REF!,$B11,#REF!,$C11) -> #REF! | AE11: =SUMIFS(#REF!,#REF!,$B11,#REF!,$C11) -> #REF! | AF11: =SUMIFS(#REF!,#REF!,$B11,#REF!,$C11) -> #REF! | AH11: =IF(MONTH(TODAY())>=$D11,K11-H11,"") | AI11: =IF(MONTH(TODAY())>=$D11,L11-I11,"") | AJ11: =IF(MONTH(TODAY())>=$D11,M11-J11,"") | AL11: =IF(MONTH(TODAY())>=$D11,AD11-X11,"") | AM11: =IF(MONTH(TODAY())>=$D11,AE11-Y11,"") | AN11: =IF(MONTH(TODAY())>=$D11,AF11-Z11,"") | AP11: =IF(MONTH(TODAY())>=$D11,AD11-AA11,"") | AQ11: =IF(MONTH(TODAY())>=$D11,AE11-AB11,"") | AR11: =IF(MONTH(TODAY())>=$D11,AF11-AC11,"")
B12: >=7/1/24 | C12: <8/1/24 | D12: 7 | E12: =CONCATENATE(LEFT(B12,FIND(">=",B12) + 1),RIGHT(C12,LEN(C12) - (FIND("<",C12)))) -> >=8/1/24 | F12: July | G12: =J12/$J$19 -> 0.0641 | H12: =H61+H101 -> 7 | I12: =I61+I101 -> 106.44901 | J12: 224350 | K12: =COUNTIFS(#REF!,$B12,#REF!,$C12) -> #REF! | L12: =SUMIFS(#REF!,#REF!,$B12,#REF!,$C12) -> #REF! | M12: =SUMIFS(#REF!,#REF!,$B12,#REF!,$C12) -> #REF! | N12: =COUNTIFS(#REF!,$B12,#REF!,$C12) -> #REF! | O12: =COUNTIFS(#REF!,$B12,#REF!,$C12) -> #REF! | P12: =IF(MONTH(TODAY())>=$D12,COUNTIFS(#REF!,$C12)-COUNTIFS(#REF!,$C12),"") | R12: =IF(MONTH(TODAY())>=$D12,COUNTIFS(#REF!,$C12)-COUNTIFS(#REF!,$C12),"") | S12: =COUNTIFS(#REF!,$B12,#REF!,$C12) -> #REF! | T12: =COUNTIFS(#REF!,$B12,#REF!,$C12) -> #REF! | U12: =IF(MONTH(TODAY())>=$D12,COUNTIFS(#REF!,$C12)-COUNTIFS(#REF!,$C12),"") | W12: =IF(MONTH(TODAY())>=$D12,COUNTIFS(#REF!,$C12)-COUNTIFS(#REF!,$C12),"") | X12: 12 | Y12: =Y61+Y101 -> 163.5 | Z12: =Z61+Z101 -> 377263.22 | AA12: =COUNTIFS(#REF!,$B12,#REF!,$C12) -> #REF! | AB12: =SUMIFS(#REF!,#REF!,$B12,#REF!,$C12) -> #REF! | AC12: =SUMIFS(#REF!,#REF!,$B12,#REF!,$C12) -> #REF! | AD12: =COUNTIFS(#REF!,$B12,#REF!,$C12) -> #REF! | AE12: =SUMIFS(#REF!,#REF!,$B12,#REF!,$C12) -> #REF! | AF12: =SUMIFS(#REF!,#REF!,$B12,#REF!,$C12) -> #REF! | AH12: =IF(MONTH(TODAY())>=$D12,K12-H12,"") | AI12: =IF(MONTH(TODAY())>=$D12,L12-I12,"") | AJ12: =IF(MONTH(TODAY())>=$D12,M12-J12,"") | AL12: =IF(MONTH(TODAY())>=$D12,AD12-X12,"") | AM12: =IF(MONTH(TODAY())>=$D12,AE12-Y12,"") | AN12: =IF(MONTH(TODAY())>=$D12,AF12-Z12,"") | AP12: =IF(MONTH(TODAY())>=$D12,AD12-AA12,"") | AQ12: =IF(MONTH(TODAY())>=$D12,AE12-AB12,"") | AR12: =IF(MONTH(TODAY())>=$D12,AF12-AC12,"")
B13: >=8/1/24 | C13: <9/1/24 | D13: 8 | E13: =CONCATENATE(LEFT(B13,FIND(">=",B13) + 1),RIGHT(C13,LEN(C13) - (FIND("<",C13)))) -> >=9/1/24 | F13: August | G13: =J13/$J$19 -> 0.0933 | H13: =H62+H102 -> 10 | I13: =I62+I102 -> 143.2551 | J13: 326550 | K13: =COUNTIFS(#REF!,$B13,#REF!,$C13) -> #REF! | L13: =SUMIFS(#REF!,#REF!,$B13,#REF!,$C13) -> #REF! | M13: =SUMIFS(#REF!,#REF!,$B13,#REF!,$C13) -> #REF! | N13: =COUNTIFS(#REF!,$B13,#REF!,$C13) -> #REF! | O13: =COUNTIFS(#REF!,$B13,#REF!,$C13) -> #REF! | P13: =IF(MONTH(TODAY())>=$D13,COUNTIFS(#REF!,$C13)-COUNTIFS(#REF!,$C13),"") | R13: =IF(MONTH(TODAY())>=$D13,COUNTIFS(#REF!,$C13)-COUNTIFS(#REF!,$C13),"") | S13: =COUNTIFS(#REF!,$B13,#REF!,$C13) -> #REF! | T13: =COUNTIFS(#REF!,$B13,#REF!,$C13) -> #REF! | U13: =IF(MONTH(TODAY())>=$D13,COUNTIFS(#REF!,$C13)-COUNTIFS(#REF!,$C13),"") | W13: =IF(MONTH(TODAY())>=$D13,COUNTIFS(#REF!,$C13)-COUNTIFS(#REF!,$C13),"") | X13: 12 | Y13: =Y62+Y102 -> 163.5 | Z13: =Z62+Z102 -> 377263.22 | AA13: =COUNTIFS(#REF!,$B13,#REF!,$C13) -> #REF! | AB13: =SUMIFS(#REF!,#REF!,$B13,#REF!,$C13) -> #REF! | AC13: =SUMIFS(#REF!,#REF!,$B13,#REF!,$C13) -> #REF! | AD13: =COUNTIFS(#REF!,$B13,#REF!,$C13) -> #REF! | AE13: =SUMIFS(#REF!,#REF!,$B13,#REF!,$C13) -> #REF! | AF13: =SUMIFS(#REF!,#REF!,$B13,#REF!,$C13) -> #REF! | AH13: =IF(MONTH(TODAY())>=$D13,K13-H13,"") | AI13: =IF(MONTH(TODAY())>=$D13,L13-I13,"") | AJ13: =IF(MONTH(TODAY())>=$D13,M13-J13,"") | AL13: =IF(MONTH(TODAY())>=$D13,AD13-X13,"") | AM13: =IF(MONTH(TODAY())>=$D13,AE13-Y13,"") | AN13: =IF(MONTH(TODAY())>=$D13,AF13-Z13,"") | AP13: =IF(MONTH(TODAY())>=$D13,AD13-AA13,"") | AQ13: =IF(MONTH(TODAY())>=$D13,AE13-AB13,"") | AR13: =IF(MONTH(TODAY())>=$D13,AF13-AC13,"")
B14: >=9/1/24 | C14: <10/1/24 | D14: 9 | E14: =CONCATENATE(LEFT(B14,FIND(">=",B14) + 1),RIGHT(C14,LEN(C14) - (FIND("<",C14)))) -> >=10/1/24 | F14: September | G14: =J14/$J$19 -> 0.0829 | H14: =H63+H103 -> 9 | I14: =I63+I103 -> 130.14608 | J14: 290150 | K14: =COUNTIFS(#REF!,$B14,#REF!,$C14) -> #REF! | L14: =SUMIFS(#REF!,#REF!,$B14,#REF!,$C14) -> #REF! | M14: =SUMIFS(#REF!,#REF!,$B14,#REF!,$C14) -> #REF! | N14: =COUNTIFS(#REF!,$B14,#REF!,$C14) -> #REF! | O14: =COUNTIFS(#REF!,$B14,#REF!,$C14) -> #REF! | P14: =IF(MONTH(TODAY())>=$D14,COUNTIFS(#REF!,$C14)-COUNTIFS(#REF!,$C14),"") | R14: =IF(MONTH(TODAY())>=$D14,COUNTIFS(#REF!,$C14)-COUNTIFS(#REF!,$C14),"") | S14: =COUNTIFS(#REF!,$B14,#REF!,$C14) -> #REF! | T14: =COUNTIFS(#REF!,$B14,#REF!,$C14) -> #REF! | U14: =IF(MONTH(TODAY())>=$D14,COUNTIFS(#REF!,$C14)-COUNTIFS(#REF!,$C14),"") | W14: =IF(MONTH(TODAY())>=$D14,COUNTIFS(#REF!,$C14)-COUNTIFS(#REF!,$C14),"") | X14: 11 | Y14: =Y63+Y103 -> 153.5 | Z14: =Z63+Z103 -> 349495.11 | AA14: =COUNTIFS(#REF!,$B14,#REF!,$C14) -> #REF! | AB14: =SUMIFS(#REF!,#REF!,$B14,#REF!,$C14) -> #REF! | AC14: =SUMIFS(#REF!,#REF!,$B14,#REF!,$C14) -> #REF! | AD14: =COUNTIFS(#REF!,$B14,#REF!,$C14) -> #REF! | AE14: =SUMIFS(#REF!,#REF!,$B14,#REF!,$C14) -> #REF! | AF14: =SUMIFS(#REF!,#REF!,$B14,#REF!,$C14) -> #REF! | AH14: =IF(MONTH(TODAY())>=$D14,K14-H14,"") | AI14: =IF(MONTH(TODAY())>=$D14,L14-I14,"") | AJ14: =IF(MONTH(TODAY())>=$D14,M14-J14,"") | AL14: =IF(MONTH(TODAY())>=$D14,AD14-X14,"") | AM14: =IF(MONTH(TODAY())>=$D14,AE14-Y14,"") | AN14: =IF(MONTH(TODAY())>=$D14,AF14-Z14,"") | AP14: =IF(MONTH(TODAY())>=$D14,AD14-AA14,"") | AQ14: =IF(MONTH(TODAY())>=$D14,AE14-AB14,"") | AR14: =IF(MONTH(TODAY())>=$D14,AF14-AC14,"")
B15: >=10/1/24 | C15: <11/1/24 | D15: 10 | E15: =CONCATENATE(LEFT(B15,FIND(">=",B15) + 1),RIGHT(C15,LEN(C15) - (FIND("<",C15)))) -> >=11/1/24 | F15: October | G15: =J15/$J$19 -> 0.1056 | H15: =H64+H104 -> 13 | I15: =I64+I104 -> 133.10698 | J15: 369600 | K15: =COUNTIFS(#REF!,$B15,#REF!,$C15) -> #REF! | L15: =SUMIFS(#REF!,#REF!,$B15,#REF!,$C15) -> #REF! | M15: =SUMIFS(#REF!,#REF!,$B15,#REF!,$C15) -> #REF! | N15: =COUNTIFS(#REF!,$B15,#REF!,$C15) -> #REF! | O15: =COUNTIFS(#REF!,$B15,#REF!,$C15) -> #REF! | P15: =IF(MONTH(TODAY())>=$D15,COUNTIFS(#REF!,$C15)-COUNTIFS(#REF!,$C15),"") | R15: =IF(MONTH(TODAY())>=$D15,COUNTIFS(#REF!,$C15)-COUNTIFS(#REF!,$C15),"") | S15: =COUNTIFS(#REF!,$B15,#REF!,$C15) -> #REF! | T15: =COUNTIFS(#REF!,$B15,#REF!,$C15) -> #REF! | U15: =IF(MONTH(TODAY())>=$D15,COUNTIFS(#REF!,$C15)-COUNTIFS(#REF!,$C15),"") | W15: =IF(MONTH(TODAY())>=$D15,COUNTIFS(#REF!,$C15)-COUNTIFS(#REF!,$C15),"") | X15: 12 | Y15: =Y64+Y104 -> 163.5 | Z15: =Z64+Z104 -> 377263.22 | AA15: =COUNTIFS(#REF!,$B15,#REF!,$C15) -> #REF! | AB15: =SUMIFS(#REF!,#REF!,$B15,#REF!,$C15) -> #REF! | AC15: =SUMIFS(#REF!,#REF!,$B15,#REF!,$C15) -> #REF! | AD15: =COUNTIFS(#REF!,$B15,#REF!,$C15) -> #REF! | AE15: =SUMIFS(#REF!,#REF!,$B15,#REF!,$C15) -> #REF! | AF15: =SUMIFS(#REF!,#REF!,$B15,#REF!,$C15) -> #REF! | AH15: =IF(MONTH(TODAY())>=$D15,K15-H15,"") | AI15: =IF(MONTH(TODAY())>=$D15,L15-I15,"") | AJ15: =IF(MONTH(TODAY())>=$D15,M15-J15,"") | AL15: =IF(MONTH(TODAY())>=$D15,AD15-X15,"") | AM15: =IF(MONTH(TODAY())>=$D15,AE15-Y15,"") | AN15: =IF(MONTH(TODAY())>=$D15,AF15-Z15,"") | AP15: =IF(MONTH(TODAY())>=$D15,AD15-AA15,"") | AQ15: =IF(MONTH(TODAY())>=$D15,AE15-AB15,"") | AR15: =IF(MONTH(TODAY())>=$D15,AF15-AC15,"")
B16: >=11/1/24 | C16: <12/1/24 | D16: 11 | E16: =CONCATENATE(LEFT(B16,FIND(">=",B16) + 1),RIGHT(C16,LEN(C16) - (FIND("<",C16)))) -> >=12/1/24 | F16: November | G16: =J16/$J$19 -> 0.0653 | H16: =H65+H105 -> 8 | I16: =I65+I105 -> 82.309524 | J16: 228550 | K16: =COUNTIFS(#REF!,$B16,#REF!,$C16) -> #REF! | L16: =SUMIFS(#REF!,#REF!,$B16,#REF!,$C16) -> #REF! | M16: =SUMIFS(#REF!,#REF!,$B16,#REF!,$C16) -> #REF! | N16: =COUNTIFS(#REF!,$B16,#REF!,$C16) -> #REF! | O16: =COUNTIFS(#REF!,$B16,#REF!,$C16) -> #REF! | P16: =IF(MONTH(TODAY())>=$D16,COUNTIFS(#REF!,$C16)-COUNTIFS(#REF!,$C16),"") | R16: =IF(MONTH(TODAY())>=$D16,COUNTIFS(#REF!,$C16)-COUNTIFS(#REF!,$C16),"") | S16: =COUNTIFS(#REF!,$B16,#REF!,$C16) -> #REF! | T16: =COUNTIFS(#REF!,$B16,#REF!,$C16) -> #REF! | U16: =IF(MONTH(TODAY())>=$D16,COUNTIFS(#REF!,$C16)-COUNTIFS(#REF!,$C16),"") | W16: =IF(MONTH(TODAY())>=$D16,COUNTIFS(#REF!,$C16)-COUNTIFS(#REF!,$C16),"") | X16: 9 | Y16: =Y65+Y105 -> 90 | Z16: =Z65+Z105 -> 249912.94 | AA16: =COUNTIFS(#REF!,$B16,#REF!,$C16) -> #REF! | AB16: =SUMIFS(#REF!,#REF!,$B16,#REF!,$C16) -> #REF! | AC16: =SUMIFS(#REF!,#REF!,$B16,#REF!,$C16) -> #REF! | AD16: =COUNTIFS(#REF!,$B16,#REF!,$C16) -> #REF! | AE16: =SUMIFS(#REF!,#REF!,$B16,#REF!,$C16) -> #REF! | AF16: =SUMIFS(#REF!,#REF!,$B16,#REF!,$C16) -> #REF! | AH16: =IF(MONTH(TODAY())>=$D16,K16-H16,"") | AI16: =IF(MONTH(TODAY())>=$D16,L16-I16,"") | AJ16: =IF(MONTH(TODAY())>=$D16,M16-J16,"") | AL16: =IF(MONTH(TODAY())>=$D16,AD16-X16,"") | AM16: =IF(MONTH(TODAY())>=$D16,AE16-Y16,"") | AN16: =IF(MONTH(TODAY())>=$D16,AF16-Z16,"") | AP16: =IF(MONTH(TODAY())>=$D16,AD16-AA16,"") | AQ16: =IF(MONTH(TODAY())>=$D16,AE16-AB16,"") | AR16: =IF(MONTH(TODAY())>=$D16,AF16-AC16,"")
B17: >=12/1/24 | C17: <1/1/25 | D17: 12 | E17: =CONCATENATE(LEFT(B17,FIND(">=",B17) + 1),RIGHT(C17,LEN(C17) - (FIND("<",C17)))) -> >=1/1/25 | F17: December | G17: =J17/$J$19 -> 0.0811 | H17: =H66+H106 -> 10 | I17: =I66+I106 -> 102.22515 | J17: 283850 | K17: =COUNTIFS(#REF!,$B17,#REF!,$C17) -> #REF! | L17: =SUMIFS(#REF!,#REF!,$B17,#REF!,$C17) -> #REF! | M17: =SUMIFS(#REF!,#REF!,$B17,#REF!,$C17) -> #REF! | N17: =COUNTIFS(#REF!,$B17,#REF!,$C17) -> #REF! | O17: =COUNTIFS(#REF!,$B17,#REF!,$C17) -> #REF! | P17: =IF(MONTH(TODAY())>=$D17,COUNTIFS(#REF!,$C17)-COUNTIFS(#REF!,$C17),"") | R17: =IF(MONTH(TODAY())>=$D17,COUNTIFS(#REF!,$C17)-COUNTIFS(#REF!,$C17),"") | S17: =COUNTIFS(#REF!,$B17,#REF!,$C17) -> #REF! | T17: =COUNTIFS(#REF!,$B17,#REF!,$C17) -> #REF! | U17: =IF(MONTH(TODAY())>=$D17,COUNTIFS(#REF!,$C17)-COUNTIFS(#REF!,$C17),"") | W17: =IF(MONTH(TODAY())>=$D17,COUNTIFS(#REF!,$C17)-COUNTIFS(#REF!,$C17),"") | X17: 6 | Y17: =Y66+Y106 -> 60 | Z17: =Z66+Z106 -> 166608.63 | AA17: =COUNTIFS(#REF!,$B17,#REF!,$C17) -> #REF! | AB17: =SUMIFS(#REF!,#REF!,$B17,#REF!,$C17) -> #REF! | AC17: =SUMIFS(#REF!,#REF!,$B17,#REF!,$C17) -> #REF! | AD17: =COUNTIFS(#REF!,$B17,#REF!,$C17) -> #REF! | AE17: =SUMIFS(#REF!,#REF!,$B17,#REF!,$C17) -> #REF! | AF17: =SUMIFS(#REF!,#REF!,$B17,#REF!,$C17) -> #REF! | AH17: =IF(MONTH(TODAY())>=$D17,K17-H17,"") | AI17: =IF(MONTH(TODAY())>=$D17,L17-I17,"") | AJ17: =IF(MONTH(TODAY())>=$D17,M17-J17,"") | AL17: =IF(MONTH(TODAY())>=$D17,AD17-X17,"") | AM17: =IF(MONTH(TODAY())>=$D17,AE17-Y17,"") | AN17: =IF(MONTH(TODAY())>=$D17,AF17-Z17,"") | AP17: =IF(MONTH(TODAY())>=$D17,AD17-AA17,"") | AQ17: =IF(MONTH(TODAY())>=$D17,AE17-AB17,"") | AR17: =IF(MONTH(TODAY())>=$D17,AF17-AC17,"")
B18: >=1/1/25 | C18: <1/1/26 | E18: =CONCATENATE(LEFT(B18,FIND(">=",B18) + 1),RIGHT(C18,LEN(C18) - (FIND("<",C18)))) -> >=1/1/26 | F18: 2025 | G18: N/A | K18: =COUNTIFS(#REF!,$B18,#REF!,$C18) -> #REF! | L18: =SUMIFS(#REF!,#REF!,$B18,#REF!,$C18) -> #REF! | M18: =SUMIFS(#REF!,#REF!,$B18,#REF!,$C18) -> #REF! | N18: =COUNTIFS(#REF!,$B18,#REF!,$C18) -> #REF! | O18: =COUNTIFS(#REF!,$B18,#REF!,$C18) -> #REF! | S18: =COUNTIFS(#REF!,$B18,#REF!,$C18) -> #REF! | T18: =COUNTIFS(#REF!,$B18,#REF!,$C18) -> #REF! | AA18: =COUNTIFS(#REF!,$B18,#REF!,$C18) -> #REF! | AB18: =SUMIFS(#REF!,#REF!,$B18,#REF!,$C18) -> #REF! | AC18: =SUMIFS(#REF!,#REF!,$B18,#REF!,$C18) -> #REF!
F19: Total | G19: =SUM(G6:G17) -> 1 | H19: =X19*J19/Z19 -> 112.79128 | I19: =Y19*J19/Z19 -> 1491.3513 | J19: =SUM(J6:J17) -> 3500000 | K19: =SUM(K5:K18) -> #REF! | L19: =SUM(L5:L18) -> #REF! | M19: =SUM(M5:M18) -> #REF! | N19: =SUM(N5:N18) -> #REF! | O19: =SUM(O5:O18) -> #REF! | P19: =INDEX(P5:P18,MONTH(TODAY())+1) -> #REF! | Q19: =INDEX(Q5:Q18,MONTH(TODAY())+1) | R19: =INDEX(R5:R18,MONTH(TODAY())+1) -> #REF! | S19: =SUM(S5:S18) -> #REF! | T19: =SUM(T5:T18) -> #REF! | U19: =INDEX(U5:U18,MONTH(TODAY())+1) -> #REF! | V19: =INDEX(V5:V18,MONTH(TODAY())+1) | W19: =INDEX(W5:W18,MONTH(TODAY())+1) -> #REF! | X19: =SUM(X5:X18) -> 108 | Y19: =SUM(Y5:Y18) -> 1428 | Z19: =3351323 -> 3351323 | AA19: =SUM(AA5:AA18) -> #REF! | AB19: =SUM(AB5:AB18) -> #REF! | AC19: =SUM(AC5:AC18) -> #REF! | AD19: =SUM(AD6:AD17) -> #REF! | AE19: =SUM(AE5:AE18) -> #REF! | AF19: =SUM(AF5:AF18) -> #REF! | AH19: =SUM(AH6:AH17) -> #REF! | AI19: =SUM(AI6:AI17) -> #REF! | AJ19: =SUM(AJ6:AJ17) -> #REF! | AL19: =SUM(AL5:AL18) -> #REF! | AM19: =SUM(AM5:AM18) -> #REF! | AN19: =SUM(AN5:AN18) -> #REF! | AP19: =SUM(AP5:AP18) -> #REF! | AQ19: =SUM(AQ5:AQ18) -> #REF! | AR19: =SUM(AR5:AR18) -> #REF!
F20: Total* | G20: =SUM(G6:G17) -> 1 | K20: =SUM(K6:K17) -> #REF! | L20: =SUM(L6:L17) -> #REF! | M20: =SUM(M6:M17) -> #REF! | N20: =SUM(N6:N17) -> #REF! | O20: =SUM(O6:O17) -> #REF! | S20: =SUM(S6:S17) -> #REF! | T20: =SUM(T6:T17) -> #REF! | AA20: =SUM(AA6:AA17) -> #REF! | AB20: =SUM(AB6:AB17) -> #REF! | AC20: =SUM(AC6:AC17) -> #REF! | AP20: =SUM(AP6:AP17) -> #REF! | AQ20: =SUM(AQ6:AQ17) -> #REF! | AR20: =SUM(AR6:AR17) -> #REF!
H22: *Removes 2023 and 2025 data
L23: June - September is all resi | X23: 1000 kW Resi | AH23: Positive Numbers Indicate we are ahead of schedule in terms of actual bookings | AL23: Positive Numbers Indicate we are ahead of schedule in terms of actual installations | AP23: Positive Numbers Indicate we are ahead of schedule in terms of actual installations vs what we planned on doing at contract signing (BD Actuals)
H24: $3,500,000 in bookings is the target | X24: 428 kW Commercial
H25: Since booking revenue target is 4.44% greater than installed revenue target, kW booked and QTY booked targets are taken to be 1.0444* Install Goals for 2024 | X25: 108 Jobs Total
X26: No plan as to which months the commercial projects will land in
X28: Yearly Avg kW target: 13.23kW/system (blend of resi + commercial)
H29: Yearly Avg kW target: 13.23kW/system (blend of resi + commercial)
AH33: Bookings | AL33: Installs
F34: Month | AF34: # of Months Left | AH34: Average monthly residential + commercial bookings needed to be in line with Budgeted Goals | AL34: Average monthly residential + commercial installs needed to be in line with Budgeted Goals
F35: January | AF35: 12 | AH35: =IF(MONTH(TODAY())=$D6,$AH$47/$AF35,"") | AI35: =IF(MONTH(TODAY())=$D6,$AI$47/$AF35,"") | AJ35: =IF(MONTH(TODAY())=$D6,$AJ$47/$AF35,"") | AL35: =IF(MONTH(TODAY())=$D6,$AL$47/$AF35,"") | AM35: =IF(MONTH(TODAY())=$D6,$AM$47/$AF35,"") | AN35: =IF(MONTH(TODAY())=$D6,$AN$47/AF35,"")
F36: February | AF36: 11 | AH36: =IF(MONTH(TODAY())=$D7,$AH$47/$AF36,"") | AI36: =IF(MONTH(TODAY())=$D7,$AI$47/$AF36,"") | AJ36: =IF(MONTH(TODAY())=$D7,$AJ$47/$AF36,"") | AL36: =IF(MONTH(TODAY())=$D7,$AL$47/$AF36,"") | AM36: =IF(MONTH(TODAY())=$D7,$AM$47/$AF36,"") | AN36: =IF(MONTH(TODAY())=$D7,$AN$47/AF36,"")
F37: March | AF37: 10 | AH37: =IF(MONTH(TODAY())=$D8,$AH$47/$AF37,"") -> #REF! | AI37: =IF(MONTH(TODAY())=$D8,$AI$47/$AF37,"") -> #REF! | AJ37: =IF(MONTH(TODAY())=$D8,$AJ$47/$AF37,"") -> #REF! | AL37: =IF(MONTH(TODAY())=$D8,$AL$47/$AF37,"") -> #REF! | AM37: =IF(MONTH(TODAY())=$D8,$AM$47/$AF37,"") -> #REF! | AN37: =IF(MONTH(TODAY())=$D8,$AN$47/AF37,"") -> #REF!
F38: April | AF38: 9 | AH38: =IF(MONTH(TODAY())=$D9,$AH$47/$AF38,"") | AI38: =IF(MONTH(TODAY())=$D9,$AI$47/$AF38,"") | AJ38: =IF(MONTH(TODAY())=$D9,$AJ$47/$AF38,"") | AL38: =IF(MONTH(TODAY())=$D9,$AL$47/$AF38,"") | AM38: =IF(MONTH(TODAY())=$D9,$AM$47/$AF38,"") | AN38: =IF(MONTH(TODAY())=$D9,$AN$47/AF38,"")
F39: May | AF39: 8 | AH39: =IF(MONTH(TODAY())=$D10,$AH$47/$AF39,"") | AI39: =IF(MONTH(TODAY())=$D10,$AI$47/$AF39,"") | AJ39: =IF(MONTH(TODAY())=$D10,$AJ$47/$AF39,"") | AL39: =IF(MONTH(TODAY())=$D10,$AL$47/$AF39,"") | AM39: =IF(MONTH(TODAY())=$D10,$AM$47/$AF39,"") | AN39: =IF(MONTH(TODAY())=$D10,$AN$47/AF39,"")
F40: June | AF40: 7 | AH40: =IF(MONTH(TODAY())=$D11,$AH$47/$AF40,"") | AI40: =IF(MONTH(TODAY())=$D11,$AI$47/$AF40,"") | AJ40: =IF(MONTH(TODAY())=$D11,$AJ$47/$AF40,"") | AL40: =IF(MONTH(TODAY())=$D11,$AL$47/$AF40,"") | AM40: =IF(MONTH(TODAY())=$D11,$AM$47/$AF40,"") | AN40: =IF(MONTH(TODAY())=$D11,$AN$47/AF40,"")
F41: July | AF41: 6 | AH41: =IF(MONTH(TODAY())=$D12,$AH$47/$AF41,"") | AI41: =IF(MONTH(TODAY())=$D12,$AI$47/$AF41,"") | AJ41: =IF(MONTH(TODAY())=$D12,$AJ$47/$AF41,"") | AL41: =IF(MONTH(TODAY())=$D12,$AL$47/$AF41,"") | AM41: =IF(MONTH(TODAY())=$D12,$AM$47/$AF41,"") | AN41: =IF(MONTH(TODAY())=$D12,$AN$47/AF41,"")
F42: August | AF42: 5 | AH42: =IF(MONTH(TODAY())=$D13,$AH$47/$AF42,"") | AI42: =IF(MONTH(TODAY())=$D13,$AI$47/$AF42,"") | AJ42: =IF(MONTH(TODAY())=$D13,$AJ$47/$AF42,"") | AL42: =IF(MONTH(TODAY())=$D13,$AL$47/$AF42,"") | AM42: =IF(MONTH(TODAY())=$D13,$AM$47/$AF42,"") | AN42: =IF(MONTH(TODAY())=$D13,$AN$47/AF42,"")
F43: September | AF43: 4 | AH43: =IF(MONTH(TODAY())=$D14,$AH$47/$AF43,"") | AI43: =IF(MONTH(TODAY())=$D14,$AI$47/$AF43,"") | AJ43: =IF(MONTH(TODAY())=$D14,$AJ$47/$AF43,"") | AL43: =IF(MONTH(TODAY())=$D14,$AL$47/$AF43,"") | AM43: =IF(MONTH(TODAY())=$D14,$AM$47/$AF43,"") | AN43: =IF(MONTH(TODAY())=$D14,$AN$47/AF43,"")
F44: October | AF44: 3 | AH44: =IF(MONTH(TODAY())=$D15,$AH$47/$AF44,"") | AI44: =IF(MONTH(TODAY())=$D15,$AI$47/$AF44,"") | AJ44: =IF(MONTH(TODAY())=$D15,$AJ$47/$AF44,"") | AL44: =IF(MONTH(TODAY())=$D15,$AL$47/$AF44,"") | AM44: =IF(MONTH(TODAY())=$D15,$AM$47/$AF44,"") | AN44: =IF(MONTH(TODAY())=$D15,$AN$47/AF44,"")
F45: November | AF45: 2 | AH45: =IF(MONTH(TODAY())=$D16,$AH$47/$AF45,"") | AI45: =IF(MONTH(TODAY())=$D16,$AI$47/$AF45,"") | AJ45: =IF(MONTH(TODAY())=$D16,$AJ$47/$AF45,"") | AL45: =IF(MONTH(TODAY())=$D16,$AL$47/$AF45,"") | AM45: =IF(MONTH(TODAY())=$D16,$AM$47/$AF45,"") | AN45: =IF(MONTH(TODAY())=$D16,$AN$47/AF45,"")
F46: December | AF46: 1 | AH46: =IF(MONTH(TODAY())=$D17,$AH$47/$AF46,"") | AI46: =IF(MONTH(TODAY())=$D17,$AI$47/$AF46,"") | AJ46: =IF(MONTH(TODAY())=$D17,$AJ$47/$AF46,"") | AL46: =IF(MONTH(TODAY())=$D17,$AL$47/$AF46,"") | AM46: =IF(MONTH(TODAY())=$D17,$AM$47/$AF46,"") | AN46: =IF(MONTH(TODAY())=$D17,$AN$47/AF46,"")
...

Sheet DTS Dashboard
B2: DTS Dashboard
B3: Item | C3: Month to Date Actual vs End of Month Target | G3: Year To Date
C4: Full MonthTarget | D4: Actual | E4: Target to Actual QTY | F4: Target to Actual % | G4: Target for the end of the month | H4: Actual | I4: Target to Actual QTY | J4: Target to Actual %
B5: QTY Installed | C5: =VLOOKUP(MONTH(TODAY()),'CORE METRICS +'!D5:'CORE METRICS +'!AR17,21) -> 7 | D5: =VLOOKUP(MONTH(TODAY()),'CORE METRICS +'!D5:'CORE METRICS +'!AR17,27) -> #REF! | E5: =D5-C5 -> #REF! | F5: =E5/C5 -> #REF! | G5: =H5-I5 -> #REF! | H5: {=SUM(INDEX('CORE METRICS +'!AD6:'CORE METRICS +'!AD17,0))} -> #REF! | I5: ='CORE METRICS +'!AL19 -> #REF! | J5: =I5/G5 -> #REF!
B6: kW Install | C6: =VLOOKUP(MONTH(TODAY()),'CORE METRICS +'!D5:'CORE METRICS +'!AR17,22) -> 113.5 | D6: =VLOOKUP(MONTH(TODAY()),'CORE METRICS +'!D5:'CORE METRICS +'!AR17,28) -> #REF! | E6: =D6-C6 -> #REF! | F6: =E6/C6 -> #REF! | G6: =H6-I6 -> #REF! | H6: {=SUM(INDEX('CORE METRICS +'!AE6:'CORE METRICS +'!AE17,0))} -> #REF! | I6: ='CORE METRICS +'!AM19 -> #REF! | J6: =I6/G6 -> #REF!
B7: Revenue $ Installed | C7: =VLOOKUP(MONTH(TODAY()),'CORE METRICS +'!D5:'CORE METRICS +'!AR17,23) -> 238422.69 | D7: =VLOOKUP(MONTH(TODAY()),'CORE METRICS +'!D5:'CORE METRICS +'!AR17,29) -> #REF! | E7: =D7-C7 -> #REF! | F7: =E7/C7 -> #REF! | G7: =H7-I7 -> #REF! | H7: {=SUM(INDEX('CORE METRICS +'!AD6:'CORE METRICS +'!AF17,0))} -> #REF! | I7: ='CORE METRICS +'!AN19 -> #REF! | J7: =I7/G7 -> #REF!
B8: Permits Submitted | D8: =VLOOKUP(MONTH(TODAY()),'CORE METRICS +'!D5:'CORE METRICS +'!AR17,11) -> #REF! | H8: {=SUM(INDEX('CORE METRICS +'!N6:'CORE METRICS +'!N17,0))} -> #REF!
B9: Permits Approved | D9: =VLOOKUP(MONTH(TODAY()),'CORE METRICS +'!D5:'CORE METRICS +'!AR17,12) -> #REF! | H9: {=SUM(INDEX('CORE METRICS +'!O6:'CORE METRICS +'!O17,0))} -> #REF!
B10: Jobs with Unsubmitted Permits | H10: ='CORE METRICS +'!P19 -> #REF!
B11: Outstanding Submitted Permits | H11: ='CORE METRICS +'!Q19
B12: Total Approved Permits for Uninstalled Projects | H12: ='CORE METRICS +'!R19 -> #REF!
B13: Utility Applications Submitted | D13: =VLOOKUP(MONTH(TODAY()),'CORE METRICS +'!D5:'CORE METRICS +'!AR17,16) -> #REF! | H13: {=SUM(INDEX('CORE METRICS +'!S6:'CORE METRICS +'!S17,0))} -> #REF!
B14: Utility Applications Approved | D14: =VLOOKUP(MONTH(TODAY()),'CORE METRICS +'!D5:'CORE METRICS +'!AR17,17) -> #REF! | H14: {=SUM(INDEX('CORE METRICS +'!T6:'CORE METRICS +'!T17,0))} -> #REF!
B15: Jobs with Unsubmitted Utility Applications | H15: ='CORE METRICS +'!U19 -> #REF!
B16: Outstanding Submitted Utility Applications | H16: ='CORE METRICS +'!V19
B17: Total Approved Utility Applications for Uninstalled Projects | H17: ='CORE METRICS +'!W19 -> #REF!
B18: QTY of Projects that have Full Approval to Move Forward Now | H18: =COUNTIFS(#REF!,"<>",#REF!,"<>",#REF!,"") -> #REF!
B19: QTY of Projects that do not have Full Approval to move forward now | H19: =COUNTIFS(#REF!,"<>",#REF!,"") - COUNTIFS(#REF!,"<>",#REF!,"<>",#REF!,"") -> #REF!
B20: QTY of Installed projects without PTO | H20: =COUNTIFS(#REF!,"<>",#REF!,"") -> #REF!
B21: Next Project on Calendar without full approval | H21: Crabb
B22: Days until that project | H22: =DATEDIF(TODAY(),"8/12/24","D") -> #NUM!
B23: Next Project on Calendar that we haven't submitted everything for | H23: Binsfeld
B24: Days until that project | H24: =DATEDIF(TODAY(),"09/9/24","D") -> #NUM!
B25: Permitted Project Lead Time (weeks) | G25: 8 | H25: =H22/7 -> #NUM!
B26: QTY of New Warranty Calls | D26: =IFERROR(__xludf.DUMMYFUNCTION("IMPORTRANGE(""https://docs.google.com/spreadsheets/d/1ej_V9sTbyoD-JmhHzgROxzKOy8bjZQHzmirCykaz6MQ/edit#gid=1962875292"",""Data!K5"")"),"#REF!") -> #REF! | H26: =IFERROR(__xludf.DUMMYFUNCTION("IMPORTRANGE(""https://docs.google.com/spreadsheets/d/1ej_V9sTbyoD-JmhHzgROxzKOy8bjZQHzmirCykaz6MQ/edit#gid=1962875292"",""Data!L5:L6"")"),"#REF!") -> #REF!
B27: QTY of Warranty Items Open
